
  Preparing the environment for use of 2020 stage.

The following modules were not unloaded:
  (Use "module --force purge" to unload all):

  1) Stages/2020
Setting HOROVOD_MPI_THREADS_DISABLE=1. 
cpu_bind=NONE - jrc0229, task  2  2 [12026]: mask 0xffffffffffffffffffffffffffffffffffffffffffffffffffffffffffffffff set
cpu_bind=NONE - jrc0229, task  0  0 [12028]: mask 0xffffffffffffffffffffffffffffffffffffffffffffffffffffffffffffffff set
cpu_bind=NONE - jrc0229, task  3  3 [12029]: mask 0xffffffffffffffffffffffffffffffffffffffffffffffffffffffffffffffff set
cpu_bind=NONE - jrc0229, task  1  1 [12027]: mask 0xffffffffffffffffffffffffffffffffffffffffffffffffffffffffffffffff set
Traceback (most recent call last):
  File "/p/software/jurecadc/stages/2020/software/Horovod/0.23.0-gomkl-2021-Python-3.8.5/lib/python3.8/site-packages/horovod/torch/mpi_ops.py", line 674, in _broadcast_async
    handle = getattr(mpi_lib, function)(
RuntimeError: Horovod has been shut down. This was caused by an exception on one of the ranks or an attempt to allreduce, allgather or broadcast a tensor after one of the ranks finished execution. If the shutdown was caused by an exception, you should see the exception in the log before the first shutdown message.

During handling of the above exception, another exception occurred:

Traceback (most recent call last):
  File "../../main.py", line 994, in <module>
    hvd.broadcast_parameters(smodel.state_dict(), root_rank=0)
  File "/p/software/jurecadc/stages/2020/software/Horovod/0.23.0-gomkl-2021-Python-3.8.5/lib/python3.8/site-packages/horovod/torch/functions.py", line 54, in broadcast_parameters
    handle = broadcast_async_(p, root_rank, name)
  File "/p/software/jurecadc/stages/2020/software/Horovod/0.23.0-gomkl-2021-Python-3.8.5/lib/python3.8/site-packages/horovod/torch/mpi_ops.py", line 775, in broadcast_async_
    return _broadcast_async(tensor, tensor, root_rank, name, process_set)
  File "/p/software/jurecadc/stages/2020/software/Horovod/0.23.0-gomkl-2021-Python-3.8.5/lib/python3.8/site-packages/horovod/torch/mpi_ops.py", line 678, in _broadcast_async
    raise HorovodInternalError(e)
horovod.common.exceptions.HorovodInternalError: Horovod has been shut down. This was caused by an exception on one of the ranks or an attempt to allreduce, allgather or broadcast a tensor after one of the ranks finished execution. If the shutdown was caused by an exception, you should see the exception in the log before the first shutdown message.
Traceback (most recent call last):
  File "/p/software/jurecadc/stages/2020/software/Horovod/0.23.0-gomkl-2021-Python-3.8.5/lib/python3.8/site-packages/horovod/torch/mpi_ops.py", line 674, in _broadcast_async
    handle = getattr(mpi_lib, function)(
RuntimeError: Horovod has been shut down. This was caused by an exception on one of the ranks or an attempt to allreduce, allgather or broadcast a tensor after one of the ranks finished execution. If the shutdown was caused by an exception, you should see the exception in the log before the first shutdown message.

During handling of the above exception, another exception occurred:

Traceback (most recent call last):
  File "../../main.py", line 994, in <module>
    hvd.broadcast_parameters(smodel.state_dict(), root_rank=0)
  File "/p/software/jurecadc/stages/2020/software/Horovod/0.23.0-gomkl-2021-Python-3.8.5/lib/python3.8/site-packages/horovod/torch/functions.py", line 54, in broadcast_parameters
    handle = broadcast_async_(p, root_rank, name)
  File "/p/software/jurecadc/stages/2020/software/Horovod/0.23.0-gomkl-2021-Python-3.8.5/lib/python3.8/site-packages/horovod/torch/mpi_ops.py", line 775, in broadcast_async_
    return _broadcast_async(tensor, tensor, root_rank, name, process_set)
  File "/p/software/jurecadc/stages/2020/software/Horovod/0.23.0-gomkl-2021-Python-3.8.5/lib/python3.8/site-packages/horovod/torch/mpi_ops.py", line 678, in _broadcast_async
    raise HorovodInternalError(e)
horovod.common.exceptions.HorovodInternalError: Horovod has been shut down. This was caused by an exception on one of the ranks or an attempt to allreduce, allgather or broadcast a tensor after one of the ranks finished execution. If the shutdown was caused by an exception, you should see the exception in the log before the first shutdown message.
Traceback (most recent call last):
  File "/p/software/jurecadc/stages/2020/software/Horovod/0.23.0-gomkl-2021-Python-3.8.5/lib/python3.8/site-packages/horovod/torch/mpi_ops.py", line 674, in _broadcast_async
    handle = getattr(mpi_lib, function)(
RuntimeError: Horovod has been shut down. This was caused by an exception on one of the ranks or an attempt to allreduce, allgather or broadcast a tensor after one of the ranks finished execution. If the shutdown was caused by an exception, you should see the exception in the log before the first shutdown message.

During handling of the above exception, another exception occurred:

Traceback (most recent call last):
  File "../../main.py", line 994, in <module>
    hvd.broadcast_parameters(smodel.state_dict(), root_rank=0)
  File "/p/software/jurecadc/stages/2020/software/Horovod/0.23.0-gomkl-2021-Python-3.8.5/lib/python3.8/site-packages/horovod/torch/functions.py", line 54, in broadcast_parameters
    handle = broadcast_async_(p, root_rank, name)
  File "/p/software/jurecadc/stages/2020/software/Horovod/0.23.0-gomkl-2021-Python-3.8.5/lib/python3.8/site-packages/horovod/torch/mpi_ops.py", line 775, in broadcast_async_
    return _broadcast_async(tensor, tensor, root_rank, name, process_set)
  File "/p/software/jurecadc/stages/2020/software/Horovod/0.23.0-gomkl-2021-Python-3.8.5/lib/python3.8/site-packages/horovod/torch/mpi_ops.py", line 678, in _broadcast_async
    raise HorovodInternalError(e)
horovod.common.exceptions.HorovodInternalError: Horovod has been shut down. This was caused by an exception on one of the ranks or an attempt to allreduce, allgather or broadcast a tensor after one of the ranks finished execution. If the shutdown was caused by an exception, you should see the exception in the log before the first shutdown message.
srun: error: jrc0229: tasks 1-3: Exited with exit code 1
cpu_bind=NONE - jrc0229, task  2  2 [14269]: mask 0xffffffffffffffffffffffffffffffffffffffffffffffffffffffffffffffff set
cpu_bind=NONE - jrc0229, task  1  1 [14268]: mask 0xffffffffffffffffffffffffffffffffffffffffffffffffffffffffffffffff set
cpu_bind=NONE - jrc0229, task  3  3 [14271]: mask 0xffffffffffffffffffffffffffffffffffffffffffffffffffffffffffffffff set
cpu_bind=NONE - jrc0229, task  0  0 [14272]: mask 0xffffffffffffffffffffffffffffffffffffffffffffffffffffffffffffffff set
Traceback (most recent call last):
  File "/p/software/jurecadc/stages/2020/software/Horovod/0.23.0-gomkl-2021-Python-3.8.5/lib/python3.8/site-packages/horovod/torch/mpi_ops.py", line 674, in _broadcast_async
    handle = getattr(mpi_lib, function)(
RuntimeError: Horovod has been shut down. This was caused by an exception on one of the ranks or an attempt to allreduce, allgather or broadcast a tensor after one of the ranks finished execution. If the shutdown was caused by an exception, you should see the exception in the log before the first shutdown message.

During handling of the above exception, another exception occurred:

Traceback (most recent call last):
  File "../../main.py", line 994, in <module>
Traceback (most recent call last):
  File "/p/software/jurecadc/stages/2020/software/Horovod/0.23.0-gomkl-2021-Python-3.8.5/lib/python3.8/site-packages/horovod/torch/mpi_ops.py", line 674, in _broadcast_async
    hvd.broadcast_parameters(smodel.state_dict(), root_rank=0)
  File "/p/software/jurecadc/stages/2020/software/Horovod/0.23.0-gomkl-2021-Python-3.8.5/lib/python3.8/site-packages/horovod/torch/functions.py", line 54, in broadcast_parameters
    handle = getattr(mpi_lib, function)(
RuntimeError: Horovod has been shut down. This was caused by an exception on one of the ranks or an attempt to allreduce, allgather or broadcast a tensor after one of the ranks finished execution. If the shutdown was caused by an exception, you should see the exception in the log before the first shutdown message.

During handling of the above exception, another exception occurred:

Traceback (most recent call last):
  File "../../main.py", line 994, in <module>
    hvd.broadcast_parameters(smodel.state_dict(), root_rank=0)
  File "/p/software/jurecadc/stages/2020/software/Horovod/0.23.0-gomkl-2021-Python-3.8.5/lib/python3.8/site-packages/horovod/torch/functions.py", line 54, in broadcast_parameters
    handle = broadcast_async_(p, root_rank, name)
  File "/p/software/jurecadc/stages/2020/software/Horovod/0.23.0-gomkl-2021-Python-3.8.5/lib/python3.8/site-packages/horovod/torch/mpi_ops.py", line 775, in broadcast_async_
    handle = broadcast_async_(p, root_rank, name)
  File "/p/software/jurecadc/stages/2020/software/Horovod/0.23.0-gomkl-2021-Python-3.8.5/lib/python3.8/site-packages/horovod/torch/mpi_ops.py", line 775, in broadcast_async_
    return _broadcast_async(tensor, tensor, root_rank, name, process_set)
  File "/p/software/jurecadc/stages/2020/software/Horovod/0.23.0-gomkl-2021-Python-3.8.5/lib/python3.8/site-packages/horovod/torch/mpi_ops.py", line 678, in _broadcast_async
    return _broadcast_async(tensor, tensor, root_rank, name, process_set)
  File "/p/software/jurecadc/stages/2020/software/Horovod/0.23.0-gomkl-2021-Python-3.8.5/lib/python3.8/site-packages/horovod/torch/mpi_ops.py", line 678, in _broadcast_async
    raise HorovodInternalError(e)
horovod.common.exceptions.HorovodInternalError: Horovod has been shut down. This was caused by an exception on one of the ranks or an attempt to allreduce, allgather or broadcast a tensor after one of the ranks finished execution. If the shutdown was caused by an exception, you should see the exception in the log before the first shutdown message.
    raise HorovodInternalError(e)
horovod.common.exceptions.HorovodInternalError: Horovod has been shut down. This was caused by an exception on one of the ranks or an attempt to allreduce, allgather or broadcast a tensor after one of the ranks finished execution. If the shutdown was caused by an exception, you should see the exception in the log before the first shutdown message.
Traceback (most recent call last):
  File "/p/software/jurecadc/stages/2020/software/Horovod/0.23.0-gomkl-2021-Python-3.8.5/lib/python3.8/site-packages/horovod/torch/mpi_ops.py", line 674, in _broadcast_async
    handle = getattr(mpi_lib, function)(
RuntimeError: Horovod has been shut down. This was caused by an exception on one of the ranks or an attempt to allreduce, allgather or broadcast a tensor after one of the ranks finished execution. If the shutdown was caused by an exception, you should see the exception in the log before the first shutdown message.

During handling of the above exception, another exception occurred:

Traceback (most recent call last):
  File "../../main.py", line 994, in <module>
    hvd.broadcast_parameters(smodel.state_dict(), root_rank=0)
  File "/p/software/jurecadc/stages/2020/software/Horovod/0.23.0-gomkl-2021-Python-3.8.5/lib/python3.8/site-packages/horovod/torch/functions.py", line 54, in broadcast_parameters
    handle = broadcast_async_(p, root_rank, name)
  File "/p/software/jurecadc/stages/2020/software/Horovod/0.23.0-gomkl-2021-Python-3.8.5/lib/python3.8/site-packages/horovod/torch/mpi_ops.py", line 775, in broadcast_async_
    return _broadcast_async(tensor, tensor, root_rank, name, process_set)
  File "/p/software/jurecadc/stages/2020/software/Horovod/0.23.0-gomkl-2021-Python-3.8.5/lib/python3.8/site-packages/horovod/torch/mpi_ops.py", line 678, in _broadcast_async
    raise HorovodInternalError(e)
horovod.common.exceptions.HorovodInternalError: Horovod has been shut down. This was caused by an exception on one of the ranks or an attempt to allreduce, allgather or broadcast a tensor after one of the ranks finished execution. If the shutdown was caused by an exception, you should see the exception in the log before the first shutdown message.
srun: error: jrc0229: tasks 1-3: Exited with exit code 1
cpu_bind=NONE - jrc0229, task  1  1 [16585]: mask 0xffffffffffffffffffffffffffffffffffffffffffffffffffffffffffffffff set
cpu_bind=NONE - jrc0229, task  3  3 [16583]: mask 0xffffffffffffffffffffffffffffffffffffffffffffffffffffffffffffffff set
cpu_bind=NONE - jrc0229, task  2  2 [16582]: mask 0xffffffffffffffffffffffffffffffffffffffffffffffffffffffffffffffff set
cpu_bind=NONE - jrc0229, task  0  0 [16584]: mask 0xffffffffffffffffffffffffffffffffffffffffffffffffffffffffffffffff set
Traceback (most recent call last):
  File "/p/software/jurecadc/stages/2020/software/Horovod/0.23.0-gomkl-2021-Python-3.8.5/lib/python3.8/site-packages/horovod/torch/mpi_ops.py", line 674, in _broadcast_async
    handle = getattr(mpi_lib, function)(
RuntimeError: Horovod has been shut down. This was caused by an exception on one of the ranks or an attempt to allreduce, allgather or broadcast a tensor after one of the ranks finished execution. If the shutdown was caused by an exception, you should see the exception in the log before the first shutdown message.

During handling of the above exception, another exception occurred:

Traceback (most recent call last):
  File "../../main.py", line 994, in <module>
    hvd.broadcast_parameters(smodel.state_dict(), root_rank=0)
  File "/p/software/jurecadc/stages/2020/software/Horovod/0.23.0-gomkl-2021-Python-3.8.5/lib/python3.8/site-packages/horovod/torch/functions.py", line 54, in broadcast_parameters
    handle = broadcast_async_(p, root_rank, name)
  File "/p/software/jurecadc/stages/2020/software/Horovod/0.23.0-gomkl-2021-Python-3.8.5/lib/python3.8/site-packages/horovod/torch/mpi_ops.py", line 775, in broadcast_async_
    return _broadcast_async(tensor, tensor, root_rank, name, process_set)
  File "/p/software/jurecadc/stages/2020/software/Horovod/0.23.0-gomkl-2021-Python-3.8.5/lib/python3.8/site-packages/horovod/torch/mpi_ops.py", line 678, in _broadcast_async
    raise HorovodInternalError(e)
horovod.common.exceptions.HorovodInternalError: Horovod has been shut down. This was caused by an exception on one of the ranks or an attempt to allreduce, allgather or broadcast a tensor after one of the ranks finished execution. If the shutdown was caused by an exception, you should see the exception in the log before the first shutdown message.
Traceback (most recent call last):
  File "/p/software/jurecadc/stages/2020/software/Horovod/0.23.0-gomkl-2021-Python-3.8.5/lib/python3.8/site-packages/horovod/torch/mpi_ops.py", line 674, in _broadcast_async
    handle = getattr(mpi_lib, function)(
RuntimeError: Horovod has been shut down. This was caused by an exception on one of the ranks or an attempt to allreduce, allgather or broadcast a tensor after one of the ranks finished execution. If the shutdown was caused by an exception, you should see the exception in the log before the first shutdown message.

During handling of the above exception, another exception occurred:

Traceback (most recent call last):
  File "../../main.py", line 994, in <module>
Traceback (most recent call last):
  File "/p/software/jurecadc/stages/2020/software/Horovod/0.23.0-gomkl-2021-Python-3.8.5/lib/python3.8/site-packages/horovod/torch/mpi_ops.py", line 674, in _broadcast_async
    hvd.broadcast_parameters(smodel.state_dict(), root_rank=0)
  File "/p/software/jurecadc/stages/2020/software/Horovod/0.23.0-gomkl-2021-Python-3.8.5/lib/python3.8/site-packages/horovod/torch/functions.py", line 54, in broadcast_parameters
    handle = broadcast_async_(p, root_rank, name)
  File "/p/software/jurecadc/stages/2020/software/Horovod/0.23.0-gomkl-2021-Python-3.8.5/lib/python3.8/site-packages/horovod/torch/mpi_ops.py", line 775, in broadcast_async_
    handle = getattr(mpi_lib, function)(
RuntimeError: Horovod has been shut down. This was caused by an exception on one of the ranks or an attempt to allreduce, allgather or broadcast a tensor after one of the ranks finished execution. If the shutdown was caused by an exception, you should see the exception in the log before the first shutdown message.

During handling of the above exception, another exception occurred:

Traceback (most recent call last):
  File "../../main.py", line 994, in <module>
    return _broadcast_async(tensor, tensor, root_rank, name, process_set)
  File "/p/software/jurecadc/stages/2020/software/Horovod/0.23.0-gomkl-2021-Python-3.8.5/lib/python3.8/site-packages/horovod/torch/mpi_ops.py", line 678, in _broadcast_async
    raise HorovodInternalError(e)
horovod.common.exceptions.HorovodInternalError: Horovod has been shut down. This was caused by an exception on one of the ranks or an attempt to allreduce, allgather or broadcast a tensor after one of the ranks finished execution. If the shutdown was caused by an exception, you should see the exception in the log before the first shutdown message.
    hvd.broadcast_parameters(smodel.state_dict(), root_rank=0)
  File "/p/software/jurecadc/stages/2020/software/Horovod/0.23.0-gomkl-2021-Python-3.8.5/lib/python3.8/site-packages/horovod/torch/functions.py", line 54, in broadcast_parameters
    handle = broadcast_async_(p, root_rank, name)
  File "/p/software/jurecadc/stages/2020/software/Horovod/0.23.0-gomkl-2021-Python-3.8.5/lib/python3.8/site-packages/horovod/torch/mpi_ops.py", line 775, in broadcast_async_
    return _broadcast_async(tensor, tensor, root_rank, name, process_set)
  File "/p/software/jurecadc/stages/2020/software/Horovod/0.23.0-gomkl-2021-Python-3.8.5/lib/python3.8/site-packages/horovod/torch/mpi_ops.py", line 678, in _broadcast_async
    raise HorovodInternalError(e)
horovod.common.exceptions.HorovodInternalError: Horovod has been shut down. This was caused by an exception on one of the ranks or an attempt to allreduce, allgather or broadcast a tensor after one of the ranks finished execution. If the shutdown was caused by an exception, you should see the exception in the log before the first shutdown message.
srun: error: jrc0229: tasks 1-3: Exited with exit code 1
cpu_bind=NONE - jrc0229, task  1  1 [18856]: mask 0xffffffffffffffffffffffffffffffffffffffffffffffffffffffffffffffff set
cpu_bind=NONE - jrc0229, task  0  0 [18853]: mask 0xffffffffffffffffffffffffffffffffffffffffffffffffffffffffffffffff set
cpu_bind=NONE - jrc0229, task  3  3 [18855]: mask 0xffffffffffffffffffffffffffffffffffffffffffffffffffffffffffffffff set
cpu_bind=NONE - jrc0229, task  2  2 [18854]: mask 0xffffffffffffffffffffffffffffffffffffffffffffffffffffffffffffffff set
Traceback (most recent call last):
  File "/p/software/jurecadc/stages/2020/software/Horovod/0.23.0-gomkl-2021-Python-3.8.5/lib/python3.8/site-packages/horovod/torch/mpi_ops.py", line 674, in _broadcast_async
    handle = getattr(mpi_lib, function)(
RuntimeError: Horovod has been shut down. This was caused by an exception on one of the ranks or an attempt to allreduce, allgather or broadcast a tensor after one of the ranks finished execution. If the shutdown was caused by an exception, you should see the exception in the log before the first shutdown message.

During handling of the above exception, another exception occurred:

Traceback (most recent call last):
  File "../../main.py", line 994, in <module>
    hvd.broadcast_parameters(smodel.state_dict(), root_rank=0)
  File "/p/software/jurecadc/stages/2020/software/Horovod/0.23.0-gomkl-2021-Python-3.8.5/lib/python3.8/site-packages/horovod/torch/functions.py", line 54, in broadcast_parameters
    handle = broadcast_async_(p, root_rank, name)
  File "/p/software/jurecadc/stages/2020/software/Horovod/0.23.0-gomkl-2021-Python-3.8.5/lib/python3.8/site-packages/horovod/torch/mpi_ops.py", line 775, in broadcast_async_
    return _broadcast_async(tensor, tensor, root_rank, name, process_set)
  File "/p/software/jurecadc/stages/2020/software/Horovod/0.23.0-gomkl-2021-Python-3.8.5/lib/python3.8/site-packages/horovod/torch/mpi_ops.py", line 678, in _broadcast_async
    raise HorovodInternalError(e)
horovod.common.exceptions.HorovodInternalError: Horovod has been shut down. This was caused by an exception on one of the ranks or an attempt to allreduce, allgather or broadcast a tensor after one of the ranks finished execution. If the shutdown was caused by an exception, you should see the exception in the log before the first shutdown message.
Traceback (most recent call last):
  File "/p/software/jurecadc/stages/2020/software/Horovod/0.23.0-gomkl-2021-Python-3.8.5/lib/python3.8/site-packages/horovod/torch/mpi_ops.py", line 674, in _broadcast_async
    handle = getattr(mpi_lib, function)(
RuntimeError: Horovod has been shut down. This was caused by an exception on one of the ranks or an attempt to allreduce, allgather or broadcast a tensor after one of the ranks finished execution. If the shutdown was caused by an exception, you should see the exception in the log before the first shutdown message.

During handling of the above exception, another exception occurred:

Traceback (most recent call last):
  File "../../main.py", line 994, in <module>
    hvd.broadcast_parameters(smodel.state_dict(), root_rank=0)
  File "/p/software/jurecadc/stages/2020/software/Horovod/0.23.0-gomkl-2021-Python-3.8.5/lib/python3.8/site-packages/horovod/torch/functions.py", line 54, in broadcast_parameters
    handle = broadcast_async_(p, root_rank, name)
  File "/p/software/jurecadc/stages/2020/software/Horovod/0.23.0-gomkl-2021-Python-3.8.5/lib/python3.8/site-packages/horovod/torch/mpi_ops.py", line 775, in broadcast_async_
    return _broadcast_async(tensor, tensor, root_rank, name, process_set)
  File "/p/software/jurecadc/stages/2020/software/Horovod/0.23.0-gomkl-2021-Python-3.8.5/lib/python3.8/site-packages/horovod/torch/mpi_ops.py", line 678, in _broadcast_async
    raise HorovodInternalError(e)
horovod.common.exceptions.HorovodInternalError: Horovod has been shut down. This was caused by an exception on one of the ranks or an attempt to allreduce, allgather or broadcast a tensor after one of the ranks finished execution. If the shutdown was caused by an exception, you should see the exception in the log before the first shutdown message.
Traceback (most recent call last):
  File "/p/software/jurecadc/stages/2020/software/Horovod/0.23.0-gomkl-2021-Python-3.8.5/lib/python3.8/site-packages/horovod/torch/mpi_ops.py", line 674, in _broadcast_async
    handle = getattr(mpi_lib, function)(
RuntimeError: Horovod has been shut down. This was caused by an exception on one of the ranks or an attempt to allreduce, allgather or broadcast a tensor after one of the ranks finished execution. If the shutdown was caused by an exception, you should see the exception in the log before the first shutdown message.

During handling of the above exception, another exception occurred:

Traceback (most recent call last):
  File "../../main.py", line 994, in <module>
    hvd.broadcast_parameters(smodel.state_dict(), root_rank=0)
  File "/p/software/jurecadc/stages/2020/software/Horovod/0.23.0-gomkl-2021-Python-3.8.5/lib/python3.8/site-packages/horovod/torch/functions.py", line 54, in broadcast_parameters
    handle = broadcast_async_(p, root_rank, name)
  File "/p/software/jurecadc/stages/2020/software/Horovod/0.23.0-gomkl-2021-Python-3.8.5/lib/python3.8/site-packages/horovod/torch/mpi_ops.py", line 775, in broadcast_async_
    return _broadcast_async(tensor, tensor, root_rank, name, process_set)
  File "/p/software/jurecadc/stages/2020/software/Horovod/0.23.0-gomkl-2021-Python-3.8.5/lib/python3.8/site-packages/horovod/torch/mpi_ops.py", line 678, in _broadcast_async
    raise HorovodInternalError(e)
horovod.common.exceptions.HorovodInternalError: Horovod has been shut down. This was caused by an exception on one of the ranks or an attempt to allreduce, allgather or broadcast a tensor after one of the ranks finished execution. If the shutdown was caused by an exception, you should see the exception in the log before the first shutdown message.
srun: error: jrc0229: tasks 1-3: Exited with exit code 1
cpu_bind=NONE - jrc0229, task  1  1 [21162]: mask 0xffffffffffffffffffffffffffffffffffffffffffffffffffffffffffffffff set
cpu_bind=NONE - jrc0229, task  0  0 [21160]: mask 0xffffffffffffffffffffffffffffffffffffffffffffffffffffffffffffffff set
cpu_bind=NONE - jrc0229, task  2  2 [21161]: mask 0xffffffffffffffffffffffffffffffffffffffffffffffffffffffffffffffff set
cpu_bind=NONE - jrc0229, task  3  3 [21163]: mask 0xffffffffffffffffffffffffffffffffffffffffffffffffffffffffffffffff set
Traceback (most recent call last):
  File "../../main.py", line 1007, in <module>
    model, lossar, time_elapsed = train_model(smodel, optimizer)
  File "../../main.py", line 781, in train_model
    lossout('Average_loss_', 'Epoch', lossar, epoch,
  File "/p/project/delia-mp/cherepashkin1/circles_public/helpers.py", line 209, in lossout
    lossfig(jn(dirname, fnm), lossar,
  File "/p/project/delia-mp/cherepashkin1/circles_public/helpers.py", line 156, in lossfig
    fig = plt.figure()
  File "/p/software/jurecadc/stages/2020/software/SciPy-Stack/2021-gcccoremkl-10.3.0-2021.2.0-Python-3.8.5/lib/python3.8/site-packages/matplotlib-3.3.1-py3.8-linux-x86_64.egg/matplotlib/pyplot.py", line 671, in figure
    figManager = new_figure_manager(num, figsize=figsize,
  File "/p/software/jurecadc/stages/2020/software/SciPy-Stack/2021-gcccoremkl-10.3.0-2021.2.0-Python-3.8.5/lib/python3.8/site-packages/matplotlib-3.3.1-py3.8-linux-x86_64.egg/matplotlib/pyplot.py", line 299, in new_figure_manager
    return _backend_mod.new_figure_manager(*args, **kwargs)
  File "/p/software/jurecadc/stages/2020/software/SciPy-Stack/2021-gcccoremkl-10.3.0-2021.2.0-Python-3.8.5/lib/python3.8/site-packages/matplotlib-3.3.1-py3.8-linux-x86_64.egg/matplotlib/backend_bases.py", line 3494, in new_figure_manager
    return cls.new_figure_manager_given_figure(num, fig)
  File "/p/software/jurecadc/stages/2020/software/SciPy-Stack/2021-gcccoremkl-10.3.0-2021.2.0-Python-3.8.5/lib/python3.8/site-packages/matplotlib-3.3.1-py3.8-linux-x86_64.egg/matplotlib/backends/_backend_tk.py", line 868, in new_figure_manager_given_figure
    window = tk.Tk(className="matplotlib")
  File "/p/software/jurecadc/stages/2020/software/Python/3.8.5-GCCcore-10.3.0/lib/python3.8/tkinter/__init__.py", line 2261, in __init__
    self.tk = _tkinter.create(screenName, baseName, className, interactive, wantobjects, useTk, sync, use)
_tkinter.TclError: couldn't connect to display "localhost:17.0"
srun: error: jrc0229: tasks 1-3: Terminated
srun: error: jrc0229: task 0: Exited with exit code 1
srun: Force Terminated job step 10176398.4
cpu_bind=NONE - jrc0229, task  1  1 [23568]: mask 0xffffffffffffffffffffffffffffffffffffffffffffffffffffffffffffffff set
cpu_bind=NONE - jrc0229, task  0  0 [23569]: mask 0xffffffffffffffffffffffffffffffffffffffffffffffffffffffffffffffff set
cpu_bind=NONE - jrc0229, task  3  3 [23571]: mask 0xffffffffffffffffffffffffffffffffffffffffffffffffffffffffffffffff set
cpu_bind=NONE - jrc0229, task  2  2 [23570]: mask 0xffffffffffffffffffffffffffffffffffffffffffffffffffffffffffffffff set
Traceback (most recent call last):
  File "../../main.py", line 1007, in <module>
    model, lossar, time_elapsed = train_model(smodel, optimizer)
  File "../../main.py", line 781, in train_model
    lossout('Average_loss_', 'Epoch', lossar, epoch,
  File "/p/project/delia-mp/cherepashkin1/circles_public/helpers.py", line 209, in lossout
    lossfig(jn(dirname, fnm), lossar,
  File "/p/project/delia-mp/cherepashkin1/circles_public/helpers.py", line 156, in lossfig
    fig = plt.figure()
  File "/p/software/jurecadc/stages/2020/software/SciPy-Stack/2021-gcccoremkl-10.3.0-2021.2.0-Python-3.8.5/lib/python3.8/site-packages/matplotlib-3.3.1-py3.8-linux-x86_64.egg/matplotlib/pyplot.py", line 671, in figure
    figManager = new_figure_manager(num, figsize=figsize,
  File "/p/software/jurecadc/stages/2020/software/SciPy-Stack/2021-gcccoremkl-10.3.0-2021.2.0-Python-3.8.5/lib/python3.8/site-packages/matplotlib-3.3.1-py3.8-linux-x86_64.egg/matplotlib/pyplot.py", line 299, in new_figure_manager
    return _backend_mod.new_figure_manager(*args, **kwargs)
  File "/p/software/jurecadc/stages/2020/software/SciPy-Stack/2021-gcccoremkl-10.3.0-2021.2.0-Python-3.8.5/lib/python3.8/site-packages/matplotlib-3.3.1-py3.8-linux-x86_64.egg/matplotlib/backend_bases.py", line 3494, in new_figure_manager
    return cls.new_figure_manager_given_figure(num, fig)
  File "/p/software/jurecadc/stages/2020/software/SciPy-Stack/2021-gcccoremkl-10.3.0-2021.2.0-Python-3.8.5/lib/python3.8/site-packages/matplotlib-3.3.1-py3.8-linux-x86_64.egg/matplotlib/backends/_backend_tk.py", line 868, in new_figure_manager_given_figure
    window = tk.Tk(className="matplotlib")
  File "/p/software/jurecadc/stages/2020/software/Python/3.8.5-GCCcore-10.3.0/lib/python3.8/tkinter/__init__.py", line 2261, in __init__
    self.tk = _tkinter.create(screenName, baseName, className, interactive, wantobjects, useTk, sync, use)
_tkinter.TclError: couldn't connect to display "localhost:17.0"
srun: error: jrc0229: tasks 1-3: Terminated
srun: error: jrc0229: task 0: Exited with exit code 1
srun: Force Terminated job step 10176398.5
cpu_bind=NONE - jrc0229, task  3  3 [25984]: mask 0xffffffffffffffffffffffffffffffffffffffffffffffffffffffffffffffff set
cpu_bind=NONE - jrc0229, task  2  2 [25985]: mask 0xffffffffffffffffffffffffffffffffffffffffffffffffffffffffffffffff set
cpu_bind=NONE - jrc0229, task  0  0 [25983]: mask 0xffffffffffffffffffffffffffffffffffffffffffffffffffffffffffffffff set
cpu_bind=NONE - jrc0229, task  1  1 [25982]: mask 0xffffffffffffffffffffffffffffffffffffffffffffffffffffffffffffffff set
Traceback (most recent call last):
  File "../../main.py", line 1007, in <module>
    model, lossar, time_elapsed = train_model(smodel, optimizer)
  File "../../main.py", line 781, in train_model
    lossout('Average_loss_', 'Epoch', lossar, epoch,
  File "/p/project/delia-mp/cherepashkin1/circles_public/helpers.py", line 209, in lossout
    lossfig(jn(dirname, fnm), lossar,
  File "/p/project/delia-mp/cherepashkin1/circles_public/helpers.py", line 156, in lossfig
    fig = plt.figure()
  File "/p/software/jurecadc/stages/2020/software/SciPy-Stack/2021-gcccoremkl-10.3.0-2021.2.0-Python-3.8.5/lib/python3.8/site-packages/matplotlib-3.3.1-py3.8-linux-x86_64.egg/matplotlib/pyplot.py", line 671, in figure
    figManager = new_figure_manager(num, figsize=figsize,
  File "/p/software/jurecadc/stages/2020/software/SciPy-Stack/2021-gcccoremkl-10.3.0-2021.2.0-Python-3.8.5/lib/python3.8/site-packages/matplotlib-3.3.1-py3.8-linux-x86_64.egg/matplotlib/pyplot.py", line 299, in new_figure_manager
    return _backend_mod.new_figure_manager(*args, **kwargs)
  File "/p/software/jurecadc/stages/2020/software/SciPy-Stack/2021-gcccoremkl-10.3.0-2021.2.0-Python-3.8.5/lib/python3.8/site-packages/matplotlib-3.3.1-py3.8-linux-x86_64.egg/matplotlib/backend_bases.py", line 3494, in new_figure_manager
    return cls.new_figure_manager_given_figure(num, fig)
  File "/p/software/jurecadc/stages/2020/software/SciPy-Stack/2021-gcccoremkl-10.3.0-2021.2.0-Python-3.8.5/lib/python3.8/site-packages/matplotlib-3.3.1-py3.8-linux-x86_64.egg/matplotlib/backends/_backend_tk.py", line 868, in new_figure_manager_given_figure
    window = tk.Tk(className="matplotlib")
  File "/p/software/jurecadc/stages/2020/software/Python/3.8.5-GCCcore-10.3.0/lib/python3.8/tkinter/__init__.py", line 2261, in __init__
    self.tk = _tkinter.create(screenName, baseName, className, interactive, wantobjects, useTk, sync, use)
_tkinter.TclError: couldn't connect to display "localhost:17.0"
srun: error: jrc0229: task 0: Exited with exit code 1
srun: error: jrc0229: tasks 1-3: Terminated
srun: Force Terminated job step 10176398.6
cpu_bind=NONE - jrc0229, task  1  1 [28380]: mask 0xffffffffffffffffffffffffffffffffffffffffffffffffffffffffffffffff set
cpu_bind=NONE - jrc0229, task  3  3 [28382]: mask 0xffffffffffffffffffffffffffffffffffffffffffffffffffffffffffffffff set
cpu_bind=NONE - jrc0229, task  2  2 [28379]: mask 0xffffffffffffffffffffffffffffffffffffffffffffffffffffffffffffffff set
cpu_bind=NONE - jrc0229, task  0  0 [28381]: mask 0xffffffffffffffffffffffffffffffffffffffffffffffffffffffffffffffff set
Traceback (most recent call last):
  File "../../main.py", line 1007, in <module>
    model, lossar, time_elapsed = train_model(smodel, optimizer)
  File "../../main.py", line 781, in train_model
    lossout('Average_loss_', 'Epoch', lossar, epoch,
  File "/p/project/delia-mp/cherepashkin1/circles_public/helpers.py", line 209, in lossout
    lossfig(jn(dirname, fnm), lossar,
  File "/p/project/delia-mp/cherepashkin1/circles_public/helpers.py", line 156, in lossfig
    fig = plt.figure()
  File "/p/software/jurecadc/stages/2020/software/SciPy-Stack/2021-gcccoremkl-10.3.0-2021.2.0-Python-3.8.5/lib/python3.8/site-packages/matplotlib-3.3.1-py3.8-linux-x86_64.egg/matplotlib/pyplot.py", line 671, in figure
    figManager = new_figure_manager(num, figsize=figsize,
  File "/p/software/jurecadc/stages/2020/software/SciPy-Stack/2021-gcccoremkl-10.3.0-2021.2.0-Python-3.8.5/lib/python3.8/site-packages/matplotlib-3.3.1-py3.8-linux-x86_64.egg/matplotlib/pyplot.py", line 299, in new_figure_manager
    return _backend_mod.new_figure_manager(*args, **kwargs)
  File "/p/software/jurecadc/stages/2020/software/SciPy-Stack/2021-gcccoremkl-10.3.0-2021.2.0-Python-3.8.5/lib/python3.8/site-packages/matplotlib-3.3.1-py3.8-linux-x86_64.egg/matplotlib/backend_bases.py", line 3494, in new_figure_manager
    return cls.new_figure_manager_given_figure(num, fig)
  File "/p/software/jurecadc/stages/2020/software/SciPy-Stack/2021-gcccoremkl-10.3.0-2021.2.0-Python-3.8.5/lib/python3.8/site-packages/matplotlib-3.3.1-py3.8-linux-x86_64.egg/matplotlib/backends/_backend_tk.py", line 868, in new_figure_manager_given_figure
    window = tk.Tk(className="matplotlib")
  File "/p/software/jurecadc/stages/2020/software/Python/3.8.5-GCCcore-10.3.0/lib/python3.8/tkinter/__init__.py", line 2261, in __init__
    self.tk = _tkinter.create(screenName, baseName, className, interactive, wantobjects, useTk, sync, use)
_tkinter.TclError: couldn't connect to display "localhost:17.0"
srun: error: jrc0229: tasks 1-3: Terminated
srun: error: jrc0229: task 0: Exited with exit code 1
srun: Force Terminated job step 10176398.7
cpu_bind=NONE - jrc0229, task  2  2 [30850]: mask 0xffffffffffffffffffffffffffffffffffffffffffffffffffffffffffffffff set
cpu_bind=NONE - jrc0229, task  1  1 [30848]: mask 0xffffffffffffffffffffffffffffffffffffffffffffffffffffffffffffffff set
cpu_bind=NONE - jrc0229, task  0  0 [30847]: mask 0xffffffffffffffffffffffffffffffffffffffffffffffffffffffffffffffff set
cpu_bind=NONE - jrc0229, task  3  3 [30849]: mask 0xffffffffffffffffffffffffffffffffffffffffffffffffffffffffffffffff set
Traceback (most recent call last):
  File "../../main.py", line 1007, in <module>
    model, lossar, time_elapsed = train_model(smodel, optimizer)
  File "../../main.py", line 781, in train_model
    lossout('Average_loss_', 'Epoch', lossar, epoch,
  File "/p/project/delia-mp/cherepashkin1/circles_public/helpers.py", line 209, in lossout
    lossfig(jn(dirname, fnm), lossar,
  File "/p/project/delia-mp/cherepashkin1/circles_public/helpers.py", line 156, in lossfig
    fig = plt.figure()
  File "/p/software/jurecadc/stages/2020/software/SciPy-Stack/2021-gcccoremkl-10.3.0-2021.2.0-Python-3.8.5/lib/python3.8/site-packages/matplotlib-3.3.1-py3.8-linux-x86_64.egg/matplotlib/pyplot.py", line 671, in figure
    figManager = new_figure_manager(num, figsize=figsize,
  File "/p/software/jurecadc/stages/2020/software/SciPy-Stack/2021-gcccoremkl-10.3.0-2021.2.0-Python-3.8.5/lib/python3.8/site-packages/matplotlib-3.3.1-py3.8-linux-x86_64.egg/matplotlib/pyplot.py", line 299, in new_figure_manager
    return _backend_mod.new_figure_manager(*args, **kwargs)
  File "/p/software/jurecadc/stages/2020/software/SciPy-Stack/2021-gcccoremkl-10.3.0-2021.2.0-Python-3.8.5/lib/python3.8/site-packages/matplotlib-3.3.1-py3.8-linux-x86_64.egg/matplotlib/backend_bases.py", line 3494, in new_figure_manager
    return cls.new_figure_manager_given_figure(num, fig)
  File "/p/software/jurecadc/stages/2020/software/SciPy-Stack/2021-gcccoremkl-10.3.0-2021.2.0-Python-3.8.5/lib/python3.8/site-packages/matplotlib-3.3.1-py3.8-linux-x86_64.egg/matplotlib/backends/_backend_tk.py", line 868, in new_figure_manager_given_figure
    window = tk.Tk(className="matplotlib")
  File "/p/software/jurecadc/stages/2020/software/Python/3.8.5-GCCcore-10.3.0/lib/python3.8/tkinter/__init__.py", line 2261, in __init__
    self.tk = _tkinter.create(screenName, baseName, className, interactive, wantobjects, useTk, sync, use)
_tkinter.TclError: couldn't connect to display "localhost:17.0"
srun: error: jrc0229: tasks 1-3: Terminated
srun: error: jrc0229: task 0: Exited with exit code 1
srun: Force Terminated job step 10176398.8
cpu_bind=NONE - jrc0229, task  0  0 [1929]: mask 0xffffffffffffffffffffffffffffffffffffffffffffffffffffffffffffffff set
cpu_bind=NONE - jrc0229, task  1  1 [1931]: mask 0xffffffffffffffffffffffffffffffffffffffffffffffffffffffffffffffff set
cpu_bind=NONE - jrc0229, task  2  2 [1928]: mask 0xffffffffffffffffffffffffffffffffffffffffffffffffffffffffffffffff set
cpu_bind=NONE - jrc0229, task  3  3 [1930]: mask 0xffffffffffffffffffffffffffffffffffffffffffffffffffffffffffffffff set
srun: Job step aborted: Waiting up to 6 seconds for job step to finish.
srun: error: jrc0229: tasks 0-3: Terminated
